[2023-05-19 20:51:28,046: INFO: stage_01_load_save]: >>>>> stage one started
[2023-05-19 20:51:28,050: INFO: all_utils]: yaml file: config/config.yaml loaded successfully
[2023-05-19 20:51:28,083: INFO: all_utils]: directory is created at data/dog
[2023-05-19 20:51:28,084: ERROR: stage_01_load_save]: [WinError 3] The system cannot find the path specified: '/outside_data/dog'
Traceback (most recent call last):
  File "src/stage_01_load_save.py", line 43, in <module>
    get_data(config_path=parsed_args.config)
  File "src/stage_01_load_save.py", line 31, in get_data
    copy_file(source_download_dir, local_data_dir)
  File "src/stage_01_load_save.py", line 16, in copy_file
    list_of_files = os.listdir(source_download_dir)
FileNotFoundError: [WinError 3] The system cannot find the path specified: '/outside_data/dog'
[2023-05-19 20:51:52,190: INFO: stage_01_load_save]: >>>>> stage one started
[2023-05-19 20:51:52,194: INFO: all_utils]: yaml file: config/config.yaml loaded successfully
[2023-05-19 20:51:52,203: INFO: all_utils]: directory is created at data/dog
[2023-05-19 20:51:52,482: INFO: all_utils]: directory is created at data/cat
[2023-05-19 20:51:52,645: INFO: stage_01_load_save]: stage one completed! all the data are saved in local >>>>>

